[2025-02-09T21:08:52.222+0000] {local_task_job_runner.py:123} INFO - ::group::Pre task execution logs
[2025-02-09T21:08:52.232+0000] {taskinstance.py:2613} INFO - Dependencies all met for dep_context=non-requeueable deps ti=<TaskInstance: mgp-airflow1.run_hello_world manual__2025-02-09T21:08:50.253126+00:00 [queued]>
[2025-02-09T21:08:52.235+0000] {taskinstance.py:2613} INFO - Dependencies all met for dep_context=requeueable deps ti=<TaskInstance: mgp-airflow1.run_hello_world manual__2025-02-09T21:08:50.253126+00:00 [queued]>
[2025-02-09T21:08:52.235+0000] {taskinstance.py:2866} INFO - Starting attempt 1 of 1
[2025-02-09T21:08:52.240+0000] {taskinstance.py:2889} INFO - Executing <Task(DockerOperator): run_hello_world> on 2025-02-09 21:08:50.253126+00:00
[2025-02-09T21:08:52.243+0000] {standard_task_runner.py:72} INFO - Started process 939 to run task
[2025-02-09T21:08:52.246+0000] {standard_task_runner.py:104} INFO - Running: ['***', 'tasks', 'run', 'mgp-***1', 'run_hello_world', 'manual__2025-02-09T21:08:50.253126+00:00', '--job-id', '6', '--raw', '--subdir', 'DAGS_FOLDER/mgpMap.py', '--cfg-path', '/tmp/tmpcl4ro9ew']
[2025-02-09T21:08:52.247+0000] {standard_task_runner.py:105} INFO - Job 6: Subtask run_hello_world
[2025-02-09T21:08:52.257+0000] {logging_mixin.py:190} WARNING - /home/***/.local/lib/python3.9/site-packages/***/settings.py:209 DeprecationWarning: The sql_alchemy_conn option in [core] has been moved to the sql_alchemy_conn option in [database] - the old setting has been used, but please update your config.
[2025-02-09T21:08:52.280+0000] {task_command.py:467} INFO - Running <TaskInstance: mgp-airflow1.run_hello_world manual__2025-02-09T21:08:50.253126+00:00 [running]> on host 8214dc5e0682
[2025-02-09T21:08:52.317+0000] {taskinstance.py:3132} INFO - Exporting env vars: AIRFLOW_CTX_DAG_OWNER='***' AIRFLOW_CTX_DAG_ID='mgp-***1' AIRFLOW_CTX_TASK_ID='run_hello_world' AIRFLOW_CTX_EXECUTION_DATE='2025-02-09T21:08:50.253126+00:00' AIRFLOW_CTX_TRY_NUMBER='1' AIRFLOW_CTX_DAG_RUN_ID='manual__2025-02-09T21:08:50.253126+00:00'
[2025-02-09T21:08:52.318+0000] {taskinstance.py:731} INFO - ::endgroup::
[2025-02-09T21:08:52.332+0000] {docker.py:157} ERROR - Failed to establish connection to Docker host tcp://docker-proxy:2375: Error while fetching server API version: HTTPConnectionPool(host='docker-proxy', port=2375): Max retries exceeded with url: /version (Caused by NewConnectionError('<urllib3.connection.HTTPConnection object at 0xffff8a7a8370>: Failed to establish a new connection: [Errno -2] Name or service not known'))
[2025-02-09T21:08:52.338+0000] {taskinstance.py:3311} ERROR - Task failed with exception
Traceback (most recent call last):
  File "/home/airflow/.local/lib/python3.9/site-packages/airflow/models/taskinstance.py", line 767, in _execute_task
    result = _execute_callable(context=context, **execute_callable_kwargs)
  File "/home/airflow/.local/lib/python3.9/site-packages/airflow/models/taskinstance.py", line 733, in _execute_callable
    return ExecutionCallableRunner(
  File "/home/airflow/.local/lib/python3.9/site-packages/airflow/utils/operator_helpers.py", line 252, in run
    return self.func(*args, **kwargs)
  File "/home/airflow/.local/lib/python3.9/site-packages/airflow/models/baseoperator.py", line 417, in wrapper
    return func(self, *args, **kwargs)
  File "/home/airflow/.local/lib/python3.9/site-packages/airflow/providers/docker/operators/docker.py", line 494, in execute
    if self.force_pull or not self.cli.images(name=self.image):
  File "/home/airflow/.local/lib/python3.9/site-packages/airflow/providers/docker/operators/docker.py", line 363, in cli
    return self.hook.api_client
  File "/usr/local/lib/python3.9/functools.py", line 993, in __get__
    val = self.func(instance)
  File "/home/airflow/.local/lib/python3.9/site-packages/airflow/providers/docker/hooks/docker.py", line 161, in api_client
    raise AirflowException("Failed to establish connection to any given Docker hosts.")
airflow.exceptions.AirflowException: Failed to establish connection to any given Docker hosts.
[2025-02-09T21:08:52.340+0000] {taskinstance.py:1225} INFO - Marking task as FAILED. dag_id=mgp-***1, task_id=run_hello_world, run_id=manual__2025-02-09T21:08:50.253126+00:00, execution_date=20250209T210850, start_date=20250209T210852, end_date=20250209T210852
[2025-02-09T21:08:52.344+0000] {taskinstance.py:340} INFO - ::group::Post task execution logs
[2025-02-09T21:08:52.344+0000] {standard_task_runner.py:124} ERROR - Failed to execute job 6 for task run_hello_world (Failed to establish connection to any given Docker hosts.; 939)
Traceback (most recent call last):
  File "/home/airflow/.local/lib/python3.9/site-packages/airflow/task/task_runner/standard_task_runner.py", line 117, in _start_by_fork
    ret = args.func(args, dag=self.dag)
  File "/home/airflow/.local/lib/python3.9/site-packages/airflow/cli/cli_config.py", line 49, in command
    return func(*args, **kwargs)
  File "/home/airflow/.local/lib/python3.9/site-packages/airflow/utils/cli.py", line 116, in wrapper
    return f(*args, **kwargs)
  File "/home/airflow/.local/lib/python3.9/site-packages/airflow/cli/commands/task_command.py", line 483, in task_run
    task_return_code = _run_task_by_selected_method(args, _dag, ti)
  File "/home/airflow/.local/lib/python3.9/site-packages/airflow/cli/commands/task_command.py", line 256, in _run_task_by_selected_method
    return _run_raw_task(args, ti)
  File "/home/airflow/.local/lib/python3.9/site-packages/airflow/cli/commands/task_command.py", line 341, in _run_raw_task
    return ti._run_raw_task(
  File "/home/airflow/.local/lib/python3.9/site-packages/airflow/utils/session.py", line 97, in wrapper
    return func(*args, session=session, **kwargs)
  File "/home/airflow/.local/lib/python3.9/site-packages/airflow/models/taskinstance.py", line 3005, in _run_raw_task
    return _run_raw_task(
  File "/home/airflow/.local/lib/python3.9/site-packages/airflow/models/taskinstance.py", line 273, in _run_raw_task
    TaskInstance._execute_task_with_callbacks(
  File "/home/airflow/.local/lib/python3.9/site-packages/airflow/models/taskinstance.py", line 3159, in _execute_task_with_callbacks
    result = self._execute_task(context, task_orig)
  File "/home/airflow/.local/lib/python3.9/site-packages/airflow/models/taskinstance.py", line 3183, in _execute_task
    return _execute_task(self, context, task_orig)
  File "/home/airflow/.local/lib/python3.9/site-packages/airflow/models/taskinstance.py", line 767, in _execute_task
    result = _execute_callable(context=context, **execute_callable_kwargs)
  File "/home/airflow/.local/lib/python3.9/site-packages/airflow/models/taskinstance.py", line 733, in _execute_callable
    return ExecutionCallableRunner(
  File "/home/airflow/.local/lib/python3.9/site-packages/airflow/utils/operator_helpers.py", line 252, in run
    return self.func(*args, **kwargs)
  File "/home/airflow/.local/lib/python3.9/site-packages/airflow/models/baseoperator.py", line 417, in wrapper
    return func(self, *args, **kwargs)
  File "/home/airflow/.local/lib/python3.9/site-packages/airflow/providers/docker/operators/docker.py", line 494, in execute
    if self.force_pull or not self.cli.images(name=self.image):
  File "/home/airflow/.local/lib/python3.9/site-packages/airflow/providers/docker/operators/docker.py", line 363, in cli
    return self.hook.api_client
  File "/usr/local/lib/python3.9/functools.py", line 993, in __get__
    val = self.func(instance)
  File "/home/airflow/.local/lib/python3.9/site-packages/airflow/providers/docker/hooks/docker.py", line 161, in api_client
    raise AirflowException("Failed to establish connection to any given Docker hosts.")
airflow.exceptions.AirflowException: Failed to establish connection to any given Docker hosts.
[2025-02-09T21:08:52.380+0000] {local_task_job_runner.py:266} INFO - Task exited with return code 1
[2025-02-09T21:08:52.390+0000] {taskinstance.py:3895} INFO - 0 downstream tasks scheduled from follow-on schedule check
[2025-02-09T21:08:52.391+0000] {local_task_job_runner.py:245} INFO - ::endgroup::
